<?xml version="1.0"?>
<robot name="aidu" xmlns:xacro="http://www.ros.org/wiki/xacro">

  <xacro:macro name="material_black">
    <material name="black">
      <color rgba="0.15 0.15 0.15 1" />
    </material>
  </xacro:macro>

  <xacro:macro name="material_darkgrey">
    <material name="darkgrey">
      <color rgba="0.4 0.4 0.4 1" />
    </material>
  </xacro:macro>

  <xacro:macro name="wheel" params="name offset radius">
    <link name="${name}_link">
      <visual>
        <geometry>
          <cylinder length="0.03" radius="${radius/2}" />
        </geometry>
        <origin xyz="0 0 0" rpy="1.5708 0 0" />
        <xacro:material_black />
      </visual>
    </link>
    <joint name="${name}_joint" type="continuous">
      <parent link="base_link" />
      <child link="${name}_link" />
      <origin xyz="${offset} ${radius/2}" />
    </joint>
  </xacro:macro>

  <link name="base_link" />
  
  <link name="main_link">
    <visual>
      <geometry>
        <box size="0.57 0.46 0.08"/>
      </geometry>
      <xacro:material_darkgrey />
    </visual>
  </link>

  <xacro:wheel name="left_wheel" offset="0 -0.258" radius="0.297" />
  <xacro:wheel name="right_wheel" offset="0 0.258" radius="0.297" />

  <xacro:wheel name="left_back_wheel" offset="-0.44 -0.21" radius="0.10" />
  <xacro:wheel name="right_back_wheel" offset="-0.44 0.21" radius="0.10" />

  <link name="camera_link" />
  
  <joint name="base_main" type="fixed">
    <parent link="base_link" />
    <child link="main_link" />
    <origin xyz="-0.201 0 0.14" />
  </joint>

  <joint name="base_camera" type="fixed">
    <parent link="base_link" />
    <child link="camera_link" />
    <origin xyz="0 0 0.23" />
  </joint>

  <link name="spindlecaddy_link">
    <visual>
      <geometry>
        <box size="0.08 0.065 0.0467"/>
      </geometry>
      <xacro:material_darkgrey />
    </visual>
  </link>

  <joint name="base_spindlecaddy" type="prismatic">
    <parent link="base_link" />
    <child link="spindlecaddy_link" />
    <origin xyz="0.1 -0.2 0.7" />
    <axis xyz="0 0 1" />
    <limit lower="0" upper="0.5" effort="1000.0" velocity="0.7" />
  </joint>

  <link name="rotationalarm_link">
    <visual>
      <geometry>
        <box size="0.135 0.015 0.015"/>
      </geometry>
      <xacro:material_darkgrey />
    </visual>
  </link>

  <joint name="spindlecaddy_rotationalarm" type="revolute">
    <parent link="spindlecaddy_link" />
    <child link="rotationalarm_link" />
    <origin xyz="0.0925 0.0 0.0413" />
    <axis xyz="0 0 1" />
    <limit lower="0" upper="0.5" effort="1000.0" velocity="0.7" />
  </joint>

  <link name="webcam_link">
    <visual>
      <geometry>
        <box size="0.02 0.045 0.037"/>
      </geometry>
      <xacro:material_darkgrey />
    </visual>
  </link>

  <joint name="rotationalarm_webcam" type="fixed">
    <parent link="rotationalarm_link" />
    <child link="webcam_link" />
    <origin xyz="0.03 0 0.026" />
  </joint>

</robot>
