<?xml version="1.0"?>
<robot name="aidu" xmlns:xacro="http://www.ros.org/wiki/xacro">

  <xacro:macro name="material_black">
    <material name="black">
      <color rgba="0.15 0.15 0.15 1" />
    </material>
  </xacro:macro>

  <xacro:macro name="material_darkgrey">
    <material name="darkgrey">
      <color rgba="0.4 0.4 0.4 1" />
    </material>
  </xacro:macro>

  <xacro:macro name="material_white">
    <material name="white">
      <color rgba="1.0 1.0 1.0 1" />
    </material>
  </xacro:macro>

  <xacro:macro name="material_darkwhite">
    <material name="darkwhite">
      <color rgba="0.98 1.0 0.843 1" />
    </material>
  </xacro:macro>

  <xacro:macro name="material_orange">
    <material name="orange">
      <color rgba="1.0 0.635 0.0 1" />
    </material>
  </xacro:macro>

  <xacro:macro name="wheel" params="name offset radius">
    <link name="${name}_link">
      <visual>
        <geometry>
          <cylinder length="0.03" radius="${radius/2}" />
        </geometry>
        <origin xyz="0 0 0" rpy="1.5708 0 0" />
        <xacro:material_black />
      </visual>
    </link>
    <joint name="${name}_joint" type="continuous">
      <parent link="base_link" />
      <child link="${name}_link" />
      <origin xyz="${offset} ${radius/2}" />
    </joint>
  </xacro:macro>

  <link name="base_link" />
  
  <link name="main_link">
    <visual>
      <geometry>
        <box size="0.57 0.46 0.08"/>
      </geometry>
      <xacro:material_darkgrey />
    </visual>
  </link>

  <xacro:wheel name="left_wheel" offset="0 -0.258" radius="0.297" />
  <xacro:wheel name="right_wheel" offset="0 0.258" radius="0.297" />

  <xacro:wheel name="left_back_wheel" offset="-0.44 -0.21" radius="0.10" />
  <xacro:wheel name="right_back_wheel" offset="-0.44 0.21" radius="0.10" />

  <link name="camera_link" />
  
  <joint name="base_main" type="fixed">
    <parent link="base_link" />
    <child link="main_link" />
    <origin xyz="-0.201 0 0.14" />
  </joint>

  <joint name="base_camera" type="fixed">
    <parent link="base_link" />
    <child link="camera_link" />
    <origin xyz="0 0 0.23" />
  </joint>

  <link name="spindlecaddy_link">
    <visual>
      <origin xyz="-0.035 0.0 -0.0225" />
      <geometry>
        <box size="0.08 0.065 0.0467"/>
      </geometry>
      <xacro:material_darkgrey />
    </visual>
  </link>

  <joint name="base_spindlecaddy" type="prismatic">
    <parent link="base_link" />
    <child link="spindlecaddy_link" />
    <origin xyz="0.108 -0.1525 0.905" />
    <axis xyz="0 0 1" />
    <limit lower="0" upper="0.5" effort="1000.0" velocity="0.7" />
  </joint>

  <link name="rotationalarm_link">
    <visual>
      <origin xyz="0.06 0.0 0.0075" />
      <geometry>
        <box size="0.15 0.015 0.015"/>
      </geometry>
      <xacro:material_darkgrey />
    </visual>
  </link>

  <joint name="spindlecaddy_rotationalarm" type="revolute">
    <parent link="spindlecaddy_link" />
    <child link="rotationalarm_link" />
    <origin xyz="0.0 0.0 0.01" />
    <axis xyz="0 0 1" />
    <limit lower="-1.57" upper="1.57" effort="1000.0" velocity="3.1415" />
  </joint>

  <link name="webcam_link">
    <visual>
      <geometry>
        <box size="0.02 0.045 0.037"/>
      </geometry>
      <xacro:material_black />
    </visual>
  </link>

  <joint name="rotationalarm_webcam" type="fixed">
    <parent link="rotationalarm_link" />
    <child link="webcam_link" />
    <origin xyz="0.03 0 0.0335" />
  </joint>

  <link name="extension_link">
    <visual>
      <origin xyz="-0.07 0.0 0.0" />
      <geometry>
        <box size="0.14 0.009 0.009"/>
      </geometry>
      <xacro:material_white />
    </visual>
  </link>

  <joint name="rotationalarm_extension" type="prismatic">
    <parent link="rotationalarm_link" />
    <child link="extension_link" />
    <origin xyz="0.150 -0.001 0.0075" />
    <axis xyz="1 0 0" />
    <limit lower="0" upper="0.075" effort="1000.0" velocity="0.3" />
  </joint>

  <!-- <link name="kast_link">
    <visual>
      <origin xyz="0.0 0.0 0.0" rpy="3.1415 0.0 3.1415" />
      <geometry>
        <mesh filename="package://aidu_transforms/urdf/kast2.STL"  scale="0.001 0.001 0.001" />
      </geometry>
      <xacro:material_darkwhite />
    </visual>
  </link>

  <joint name="main_kast" type="fixed">
    <parent link="main_link" />
    <child link="kast_link" />
    <origin xyz="0.285 -0.23 1.2" />
  </joint>

  <link name="kinect_link">
    <visual>
      <origin xyz="0.0 0.0 0.0" rpy="0.0 0.0 1.57" />
      <geometry>
        <mesh filename="package://aidu_transforms/urdf/Kinect.STL"  scale="0.001 0.001 0.001" />
      </geometry>
      <xacro:material_black />
    </visual>
  </link>

  <joint name="main_kinect" type="fixed">
    <parent link="main_link" />
    <child link="kinect_link" />
    <origin xyz="0.235 -0.14 0.05" />
  </joint>

  <link name="macbook_link">
    <visual>
      <origin xyz="0.0 0.0 0.0" rpy="1.97 0.0 -1.57" />
      <geometry>
        <mesh filename="package://aidu_transforms/urdf/MacBook.STL"  scale="0.001 0.001 0.001" />
      </geometry>
      <xacro:material_black />
    </visual>
  </link>

  <joint name="main_macbook" type="fixed">
    <parent link="main_link" />
    <child link="macbook_link" />
    <origin xyz="0.1 0.21 1.18" />
  </joint>

  <link name="lade1_link">
    <visual>
      <origin xyz="0.0 0.0 0.0" rpy="1.57 0.0 0.0" />
      <geometry>
        <mesh filename="package://aidu_transforms/urdf/lade1.STL"  scale="0.001 0.001 0.001" />
      </geometry>
      <xacro:material_orange />
    </visual>
  </link>

  <joint name="main_lade1" type="fixed">
    <parent link="main_link" />
    <child link="lade1_link" />
    <origin xyz="-0.225 0.185 0.0" />
  </joint>

  <link name="lade2_link">
    <visual>
      <origin xyz="0.0 0.0 0.0" rpy="1.57 0.0 0.0" />
      <geometry>
        <mesh filename="package://aidu_transforms/urdf/lade2.STL"  scale="0.001 0.001 0.001" />
      </geometry>
      <xacro:material_orange />
    </visual>
  </link>

  <joint name="main_lade2" type="fixed">
    <parent link="main_link" />
    <child link="lade2_link" />
    <origin xyz="-0.225 0.185 0.445" />
  </joint>

  <link name="lade3_link">
    <visual>
      <origin xyz="0.0 0.0 0.0" rpy="1.57 0.0 0.0" />
      <geometry>
        <mesh filename="package://aidu_transforms/urdf/lade3.STL"  scale="0.001 0.001 0.001" />
      </geometry>
      <xacro:material_orange />
    </visual>
  </link>

  <joint name="main_lade3" type="fixed">
    <parent link="main_link" />
    <child link="lade3_link" />
    <origin xyz="-0.225 0.185 0.75" />
  </joint> -->

</robot>
